[2m2025-10-06T19:12:50.357764Z[0m [[32m[1minfo     [0m] [1mStarting the scheduler        [0m [[0m[1m[34mairflow.jobs.scheduler_job_runner.SchedulerJobRunner[0m][0m [36mloc[0m=[35mscheduler_job_runner.py:1018[0m
[2m2025-10-06T19:12:50.363522Z[0m [[32m[1minfo     [0m] [1mAdopting or resetting orphaned tasks for active dag runs[0m [[0m[1m[34mairflow.jobs.scheduler_job_runner.SchedulerJobRunner[0m][0m [36mloc[0m=[35mscheduler_job_runner.py:2240[0m
[2m2025-10-06T19:14:27.942781Z[0m [[31m[1merror    [0m] [1mException when executing SchedulerJob._run_scheduler_loop[0m [[0m[1m[34mairflow.jobs.scheduler_job_runner.SchedulerJobRunner[0m][0m [36mloc[0m=[35mscheduler_job_runner.py:1046[0m
Traceback (most recent call last):
  File "/home/thiago/git_repos/pipeline_dados_api_twitter/venv/lib/python3.10/site-packages/sqlalchemy/engine/base.py", line 1890, in _execute_context
    self.dialect.do_executemany(
  File "/home/thiago/git_repos/pipeline_dados_api_twitter/venv/lib/python3.10/site-packages/sqlalchemy/engine/default.py", line 733, in do_executemany
    cursor.executemany(statement, parameters)
sqlite3.IntegrityError: UNIQUE constraint failed: job.id

The above exception was the direct cause of the following exception:

Traceback (most recent call last):
  File "/home/thiago/git_repos/pipeline_dados_api_twitter/venv/lib/python3.10/site-packages/airflow/jobs/scheduler_job_runner.py", line 1042, in _execute
    self._run_scheduler_loop()
  File "/home/thiago/git_repos/pipeline_dados_api_twitter/venv/lib/python3.10/site-packages/airflow/jobs/scheduler_job_runner.py", line 1367, in _run_scheduler_loop
    perform_heartbeat(
  File "/home/thiago/git_repos/pipeline_dados_api_twitter/venv/lib/python3.10/site-packages/airflow/traces/tracer.py", line 58, in wrapper
    return func(*args, **kwargs)
  File "/home/thiago/git_repos/pipeline_dados_api_twitter/venv/lib/python3.10/site-packages/airflow/jobs/job.py", line 426, in perform_heartbeat
    job.heartbeat(heartbeat_callback=heartbeat_callback)
  File "/home/thiago/git_repos/pipeline_dados_api_twitter/venv/lib/python3.10/site-packages/airflow/utils/session.py", line 100, in wrapper
    return func(*args, session=session, **kwargs)
  File "/home/thiago/git_repos/pipeline_dados_api_twitter/venv/lib/python3.10/site-packages/airflow/jobs/job.py", line 249, in heartbeat
    session.commit()
  File "/home/thiago/git_repos/pipeline_dados_api_twitter/venv/lib/python3.10/site-packages/sqlalchemy/orm/session.py", line 1454, in commit
    self._transaction.commit(_to_root=self.future)
  File "/home/thiago/git_repos/pipeline_dados_api_twitter/venv/lib/python3.10/site-packages/sqlalchemy/orm/session.py", line 832, in commit
    self._prepare_impl()
  File "/home/thiago/git_repos/pipeline_dados_api_twitter/venv/lib/python3.10/site-packages/sqlalchemy/orm/session.py", line 811, in _prepare_impl
    self.session.flush()
  File "/home/thiago/git_repos/pipeline_dados_api_twitter/venv/lib/python3.10/site-packages/sqlalchemy/orm/session.py", line 3449, in flush
    self._flush(objects)
  File "/home/thiago/git_repos/pipeline_dados_api_twitter/venv/lib/python3.10/site-packages/sqlalchemy/orm/session.py", line 3588, in _flush
    with util.safe_reraise():
  File "/home/thiago/git_repos/pipeline_dados_api_twitter/venv/lib/python3.10/site-packages/sqlalchemy/util/langhelpers.py", line 70, in __exit__
    compat.raise_(
  File "/home/thiago/git_repos/pipeline_dados_api_twitter/venv/lib/python3.10/site-packages/sqlalchemy/util/compat.py", line 211, in raise_
    raise exception
  File "/home/thiago/git_repos/pipeline_dados_api_twitter/venv/lib/python3.10/site-packages/sqlalchemy/orm/session.py", line 3549, in _flush
    flush_context.execute()
  File "/home/thiago/git_repos/pipeline_dados_api_twitter/venv/lib/python3.10/site-packages/sqlalchemy/orm/unitofwork.py", line 456, in execute
    rec.execute(self)
  File "/home/thiago/git_repos/pipeline_dados_api_twitter/venv/lib/python3.10/site-packages/sqlalchemy/orm/unitofwork.py", line 630, in execute
    util.preloaded.orm_persistence.save_obj(
  File "/home/thiago/git_repos/pipeline_dados_api_twitter/venv/lib/python3.10/site-packages/sqlalchemy/orm/persistence.py", line 245, in save_obj
    _emit_insert_statements(
  File "/home/thiago/git_repos/pipeline_dados_api_twitter/venv/lib/python3.10/site-packages/sqlalchemy/orm/persistence.py", line 1097, in _emit_insert_statements
    c = connection._execute_20(
  File "/home/thiago/git_repos/pipeline_dados_api_twitter/venv/lib/python3.10/site-packages/sqlalchemy/engine/base.py", line 1710, in _execute_20
    return meth(self, args_10style, kwargs_10style, execution_options)
  File "/home/thiago/git_repos/pipeline_dados_api_twitter/venv/lib/python3.10/site-packages/sqlalchemy/sql/elements.py", line 334, in _execute_on_connection
    return connection._execute_clauseelement(
  File "/home/thiago/git_repos/pipeline_dados_api_twitter/venv/lib/python3.10/site-packages/sqlalchemy/engine/base.py", line 1577, in _execute_clauseelement
    ret = self._execute_context(
  File "/home/thiago/git_repos/pipeline_dados_api_twitter/venv/lib/python3.10/site-packages/sqlalchemy/engine/base.py", line 1953, in _execute_context
    self._handle_dbapi_exception(
  File "/home/thiago/git_repos/pipeline_dados_api_twitter/venv/lib/python3.10/site-packages/sqlalchemy/engine/base.py", line 2134, in _handle_dbapi_exception
    util.raise_(
  File "/home/thiago/git_repos/pipeline_dados_api_twitter/venv/lib/python3.10/site-packages/sqlalchemy/util/compat.py", line 211, in raise_
    raise exception
  File "/home/thiago/git_repos/pipeline_dados_api_twitter/venv/lib/python3.10/site-packages/sqlalchemy/engine/base.py", line 1890, in _execute_context
    self.dialect.do_executemany(
  File "/home/thiago/git_repos/pipeline_dados_api_twitter/venv/lib/python3.10/site-packages/sqlalchemy/engine/default.py", line 733, in do_executemany
    cursor.executemany(statement, parameters)
sqlalchemy.exc.IntegrityError: (sqlite3.IntegrityError) UNIQUE constraint failed: job.id
[SQL: INSERT INTO job (id, dag_id, state, job_type, start_date, end_date, latest_heartbeat, executor_class, hostname, unixname) VALUES (?, ?, ?, ?, ?, ?, ?, ?, ?, ?)]
[parameters: ((28, None, <JobState.RUNNING: 'running'>, 'SchedulerJob', '2025-10-06 19:12:50.337527', None, '2025-10-06 19:14:22.005689', None, 'DESKTOP-71BQCN4.localdomain', 'thiago'), (28, None, <JobState.RUNNING: 'running'>, 'SchedulerJob', '2025-10-06 19:12:50.337527', None, '2025-10-06 19:14:22.005689', None, 'DESKTOP-71BQCN4.localdomain', 'thiago'))]
(Background on this error at: https://sqlalche.me/e/14/gkpj)
[2m2025-10-06T19:14:27.958139Z[0m [[32m[1minfo     [0m] [1mShutting down LocalExecutor; waiting for running tasks to finish.  Signal again if you don't want to wait.[0m [[0m[1m[34mairflow.executors.local_executor.LocalExecutor[0m][0m [36mloc[0m=[35mlocal_executor.py:226[0m
[2m2025-10-06T19:14:27.958397Z[0m [[32m[1minfo     [0m] [1mExited execute loop           [0m [[0m[1m[34mairflow.jobs.scheduler_job_runner.SchedulerJobRunner[0m][0m [36mloc[0m=[35mscheduler_job_runner.py:1058[0m
